<?xml version="1.0"?>
<robot xmlns:xacro="http://www.ros.org/wiki/xacro">

    <link name="base_link">
    </link>

    <joint name="base_footprint_joint" type="fixed">
        <parent link="base_link"/>
        <child link="base_footprint"/>
        <origin xyz="0 0 0" rpy="0 0 0"/>
    </joint>

    <link name="base_footprint">
    </link>

    <joint name="chassis_base_joint" type="fixed">
        <parent link="base_link" />
        <child link="chassis_link" />
        <origin xyz="0 0 0" rpy="0 0 0" />
    </joint>

    <link name="chassis_link">
        <visual>
            <geometry>
                <box size="${chassis_length} ${chassis_width} ${chassis_height}" />
            </geometry>
            <origin xyz="0 0 0.12" rpy="0 0 0" />
            <material name="blue"></material>
        </visual>
    </link>

    <joint name="left_wheel_joint" type="continuous">
        <parent link="base_link" />
        <child link="left_wheel_link" />
        <origin xyz="${wheel_offset_x} ${wheel_offset_y} ${wheel_offset_z}" rpy="0 0 0" />
        <axis xyz="0 1 0" />
    </joint>

    <link name="left_wheel_link">
        <visual>
            <geometry>
                <cylinder radius="${wheel_radius}" length="${wheel_length}" />
            </geometry>


            <origin xyz="0 0 0" rpy="1.57 0 0" />
            <material name="black"></material>
        </visual>
        <collision>
            <geometry>
                <sphere radius="${wheel_radius}"/>
            </geometry>
        </collision>
    </link>

    <joint name="right_wheel_joint" type="continuous">
        <parent link="base_link" />
        <child link="right_wheel_link" />
        <origin xyz="${wheel_offset_x} ${-wheel_offset_y} ${wheel_offset_z} " rpy="0 0 0" />
        <axis xyz="0 1 0" />
    </joint>

    <link name="right_wheel_link">
        <visual>
            <geometry>
                <cylinder radius="${wheel_radius}" length="${wheel_length}" />
            </geometry>
            <origin xyz="0 0 0" rpy="1.57 0 0" />
            <material name="black"></material>
        </visual>

    </link>
    <joint name="caster_wheel_joint" type="fixed">
        <parent link="base_link" />
        <child link="caster_wheel_link" />
        <origin xyz="${caster_wheel_offset_x} 0 ${wheel_radius} " rpy="0 0 0" />
        <axis xyz="0 1 0" />
    </joint>

    <link name="caster_wheel_link">
        <visual>
            <geometry>
                <sphere radius="${caster_wheel_radius}" />
            </geometry>
            <origin xyz="0 0 0" rpy="0 0 0" />
            <material name="black"></material>
        </visual>
    </link>
    <joint name="base_lidar_joint" type="revolute">
        <parent link="base_link" />
        <child link="lidar_box_link" />
        <origin xyz="0 0 0.22" rpy="0 0 0" />
        <axis xyz="0 1 0" />
        <limit lower="-0.523" upper="0.523" effort="10" velocity="1" />
    </joint>

    <link name="lidar_box_link">
        <visual>
            <geometry>
                <box size="${lidar_base_length} ${lidar_base_width} ${lidar_base_height}" />
            </geometry>
            <origin xyz="0 0 0" rpy="0 0 0" />
            <material name="black"></material>
        </visual>
    </link>

    <joint name="lidar_box_joint" type="fixed">
        <parent link="lidar_box_link" />
        <child link="laser_frame" />
        <origin xyz="0 0 0" rpy="0 0 0" />
    </joint>

    <link name="laser_frame">

        <visual>
            <geometry>
                <cylinder radius="${lidar_top_radius}" length="${lidar_top_length}" />
            </geometry>
            <origin xyz="0 0 ${lidar_top_length}" rpy="0 0 0" />
            <material name="black"></material>
        </visual>

    </link>
</robot>